[2024-09-18 23:14:18,750]^;INFO^;190^;configuration.py^;get_training_pipeline_config()^;Training pipeline config: TrainingPipelineConfig(artifact_dir='C:\\Users\\prash\\Downloads\\Housing_mlops\\housing\\artifact')
[2024-09-18 23:14:20,085]^;INFO^;190^;configuration.py^;get_training_pipeline_config()^;Training pipeline config: TrainingPipelineConfig(artifact_dir='C:\\Users\\prash\\Downloads\\Housing_mlops\\housing\\artifact')
[2024-09-18 23:14:20,570]^;INFO^;224^;_internal.py^;_log()^;[31m[1mWARNING: This is a development server. Do not use it in a production deployment. Use a production WSGI server instead.[0m
 * Running on http://127.0.0.1:5000
[2024-09-18 23:14:20,572]^;INFO^;224^;_internal.py^;_log()^;[33mPress CTRL+C to quit[0m
[2024-09-18 23:14:32,949]^;INFO^;224^;_internal.py^;_log()^;127.0.0.1 - - [18/Sep/2024 23:14:32] "GET / HTTP/1.1" 200 -
[2024-09-18 23:14:33,002]^;INFO^;224^;_internal.py^;_log()^;127.0.0.1 - - [18/Sep/2024 23:14:33] "[36mGET /static/style.css HTTP/1.1[0m" 304 -
[2024-09-18 23:14:35,444]^;INFO^;181^;app.py^;render_log_dir()^;req_path:
[2024-09-18 23:14:35,445]^;INFO^;183^;app.py^;render_log_dir()^;Requested path: 
[2024-09-18 23:14:35,467]^;INFO^;224^;_internal.py^;_log()^;127.0.0.1 - - [18/Sep/2024 23:14:35] "GET /housing_logs HTTP/1.1" 200 -
[2024-09-18 23:14:35,523]^;INFO^;224^;_internal.py^;_log()^;127.0.0.1 - - [18/Sep/2024 23:14:35] "[36mGET /static/style.css HTTP/1.1[0m" 304 -
[2024-09-18 23:14:48,384]^;INFO^;181^;app.py^;render_log_dir()^;req_path:log_2024-07-31_00-16-22.log
[2024-09-18 23:14:48,384]^;INFO^;183^;app.py^;render_log_dir()^;Requested path: log_2024-07-31_00-16-22.log
[2024-09-18 23:14:48,454]^;ERROR^;1745^;app.py^;log_exception()^;Exception on /housing_logs/log_2024-07-31_00-16-22.log [GET]
Traceback (most recent call last):
  File "c:\Users\prash\Downloads\Housing_mlops\venv\lib\site-packages\flask\app.py", line 2529, in wsgi_app
    response = self.full_dispatch_request()
  File "c:\Users\prash\Downloads\Housing_mlops\venv\lib\site-packages\flask\app.py", line 1825, in full_dispatch_request
    rv = self.handle_user_exception(e)
  File "c:\Users\prash\Downloads\Housing_mlops\venv\lib\site-packages\flask\app.py", line 1823, in full_dispatch_request
    rv = self.dispatch_request()
  File "c:\Users\prash\Downloads\Housing_mlops\venv\lib\site-packages\flask\app.py", line 1799, in dispatch_request
    return self.ensure_sync(self.view_functions[rule.endpoint])(**view_args)
  File "app.py", line 192, in render_log_dir
    log_df=get_log_dataframe(abs_path)
  File "C:\Users\prash\Downloads\Housing_mlops\house\logger\__init__.py", line 37, in get_log_dataframe
    return log_df[["_log_message"]]
  File "c:\Users\prash\Downloads\Housing_mlops\venv\lib\site-packages\pandas\core\frame.py", line 2912, in __getitem__
    indexer = self.loc._get_listlike_indexer(key, axis=1, raise_missing=True)[1]
  File "c:\Users\prash\Downloads\Housing_mlops\venv\lib\site-packages\pandas\core\indexing.py", line 1254, in _get_listlike_indexer
    self._validate_read_indexer(keyarr, indexer, axis, raise_missing=raise_missing)
  File "c:\Users\prash\Downloads\Housing_mlops\venv\lib\site-packages\pandas\core\indexing.py", line 1298, in _validate_read_indexer
    raise KeyError(f"None of [{key}] are in the [{axis_name}]")
KeyError: "None of [Index(['_log_message'], dtype='object')] are in the [columns]"
[2024-09-18 23:14:48,509]^;INFO^;224^;_internal.py^;_log()^;127.0.0.1 - - [18/Sep/2024 23:14:48] "[35m[1mGET /housing_logs/log_2024-07-31_00-16-22.log HTTP/1.1[0m" 500 -
[2024-09-18 23:14:52,941]^;INFO^;181^;app.py^;render_log_dir()^;req_path:log_2024-09-12_23-15-06.log
[2024-09-18 23:14:52,941]^;INFO^;183^;app.py^;render_log_dir()^;Requested path: log_2024-09-12_23-15-06.log
[2024-09-18 23:14:52,975]^;ERROR^;1745^;app.py^;log_exception()^;Exception on /housing_logs/log_2024-09-12_23-15-06.log [GET]
Traceback (most recent call last):
  File "c:\Users\prash\Downloads\Housing_mlops\venv\lib\site-packages\flask\app.py", line 2529, in wsgi_app
    response = self.full_dispatch_request()
  File "c:\Users\prash\Downloads\Housing_mlops\venv\lib\site-packages\flask\app.py", line 1825, in full_dispatch_request
    rv = self.handle_user_exception(e)
  File "c:\Users\prash\Downloads\Housing_mlops\venv\lib\site-packages\flask\app.py", line 1823, in full_dispatch_request
    rv = self.dispatch_request()
  File "c:\Users\prash\Downloads\Housing_mlops\venv\lib\site-packages\flask\app.py", line 1799, in dispatch_request
    return self.ensure_sync(self.view_functions[rule.endpoint])(**view_args)
  File "app.py", line 192, in render_log_dir
    log_df=get_log_dataframe(abs_path)
  File "C:\Users\prash\Downloads\Housing_mlops\house\logger\__init__.py", line 37, in get_log_dataframe
    return log_df[["_log_message"]]
  File "c:\Users\prash\Downloads\Housing_mlops\venv\lib\site-packages\pandas\core\frame.py", line 2912, in __getitem__
    indexer = self.loc._get_listlike_indexer(key, axis=1, raise_missing=True)[1]
  File "c:\Users\prash\Downloads\Housing_mlops\venv\lib\site-packages\pandas\core\indexing.py", line 1254, in _get_listlike_indexer
    self._validate_read_indexer(keyarr, indexer, axis, raise_missing=raise_missing)
  File "c:\Users\prash\Downloads\Housing_mlops\venv\lib\site-packages\pandas\core\indexing.py", line 1298, in _validate_read_indexer
    raise KeyError(f"None of [{key}] are in the [{axis_name}]")
KeyError: "None of [Index(['_log_message'], dtype='object')] are in the [columns]"
[2024-09-18 23:14:52,978]^;INFO^;224^;_internal.py^;_log()^;127.0.0.1 - - [18/Sep/2024 23:14:52] "[35m[1mGET /housing_logs/log_2024-09-12_23-15-06.log HTTP/1.1[0m" 500 -
[2024-09-18 23:14:56,502]^;INFO^;181^;app.py^;render_log_dir()^;req_path:log_2024-09-12_23-15-06.log
[2024-09-18 23:14:56,503]^;INFO^;183^;app.py^;render_log_dir()^;Requested path: log_2024-09-12_23-15-06.log
[2024-09-18 23:14:56,509]^;ERROR^;1745^;app.py^;log_exception()^;Exception on /housing_logs/log_2024-09-12_23-15-06.log [GET]
Traceback (most recent call last):
  File "c:\Users\prash\Downloads\Housing_mlops\venv\lib\site-packages\flask\app.py", line 2529, in wsgi_app
    response = self.full_dispatch_request()
  File "c:\Users\prash\Downloads\Housing_mlops\venv\lib\site-packages\flask\app.py", line 1825, in full_dispatch_request
    rv = self.handle_user_exception(e)
  File "c:\Users\prash\Downloads\Housing_mlops\venv\lib\site-packages\flask\app.py", line 1823, in full_dispatch_request
    rv = self.dispatch_request()
  File "c:\Users\prash\Downloads\Housing_mlops\venv\lib\site-packages\flask\app.py", line 1799, in dispatch_request
    return self.ensure_sync(self.view_functions[rule.endpoint])(**view_args)
  File "app.py", line 192, in render_log_dir
    log_df=get_log_dataframe(abs_path)
  File "C:\Users\prash\Downloads\Housing_mlops\house\logger\__init__.py", line 37, in get_log_dataframe
    return log_df[["_log_message"]]
  File "c:\Users\prash\Downloads\Housing_mlops\venv\lib\site-packages\pandas\core\frame.py", line 2912, in __getitem__
    indexer = self.loc._get_listlike_indexer(key, axis=1, raise_missing=True)[1]
  File "c:\Users\prash\Downloads\Housing_mlops\venv\lib\site-packages\pandas\core\indexing.py", line 1254, in _get_listlike_indexer
    self._validate_read_indexer(keyarr, indexer, axis, raise_missing=raise_missing)
  File "c:\Users\prash\Downloads\Housing_mlops\venv\lib\site-packages\pandas\core\indexing.py", line 1298, in _validate_read_indexer
    raise KeyError(f"None of [{key}] are in the [{axis_name}]")
KeyError: "None of [Index(['_log_message'], dtype='object')] are in the [columns]"
[2024-09-18 23:14:56,510]^;INFO^;224^;_internal.py^;_log()^;127.0.0.1 - - [18/Sep/2024 23:14:56] "[35m[1mGET /housing_logs/log_2024-09-12_23-15-06.log HTTP/1.1[0m" 500 -
[2024-09-18 23:15:49,778]^;INFO^;181^;app.py^;render_log_dir()^;req_path:log_2024-09-12_23-33-42.log
[2024-09-18 23:15:49,779]^;INFO^;183^;app.py^;render_log_dir()^;Requested path: log_2024-09-12_23-33-42.log
[2024-09-18 23:15:49,804]^;ERROR^;1745^;app.py^;log_exception()^;Exception on /housing_logs/log_2024-09-12_23-33-42.log [GET]
Traceback (most recent call last):
  File "c:\Users\prash\Downloads\Housing_mlops\venv\lib\site-packages\flask\app.py", line 2529, in wsgi_app
    response = self.full_dispatch_request()
  File "c:\Users\prash\Downloads\Housing_mlops\venv\lib\site-packages\flask\app.py", line 1825, in full_dispatch_request
    rv = self.handle_user_exception(e)
  File "c:\Users\prash\Downloads\Housing_mlops\venv\lib\site-packages\flask\app.py", line 1823, in full_dispatch_request
    rv = self.dispatch_request()
  File "c:\Users\prash\Downloads\Housing_mlops\venv\lib\site-packages\flask\app.py", line 1799, in dispatch_request
    return self.ensure_sync(self.view_functions[rule.endpoint])(**view_args)
  File "app.py", line 192, in render_log_dir
    log_df=get_log_dataframe(abs_path)
  File "C:\Users\prash\Downloads\Housing_mlops\house\logger\__init__.py", line 37, in get_log_dataframe
    return log_df[["_log_message"]]
  File "c:\Users\prash\Downloads\Housing_mlops\venv\lib\site-packages\pandas\core\frame.py", line 2912, in __getitem__
    indexer = self.loc._get_listlike_indexer(key, axis=1, raise_missing=True)[1]
  File "c:\Users\prash\Downloads\Housing_mlops\venv\lib\site-packages\pandas\core\indexing.py", line 1254, in _get_listlike_indexer
    self._validate_read_indexer(keyarr, indexer, axis, raise_missing=raise_missing)
  File "c:\Users\prash\Downloads\Housing_mlops\venv\lib\site-packages\pandas\core\indexing.py", line 1298, in _validate_read_indexer
    raise KeyError(f"None of [{key}] are in the [{axis_name}]")
KeyError: "None of [Index(['_log_message'], dtype='object')] are in the [columns]"
[2024-09-18 23:15:49,805]^;INFO^;224^;_internal.py^;_log()^;127.0.0.1 - - [18/Sep/2024 23:15:49] "[35m[1mGET /housing_logs/log_2024-09-12_23-33-42.log HTTP/1.1[0m" 500 -
[2024-09-18 23:22:39,195]^;INFO^;224^;_internal.py^;_log()^;127.0.0.1 - - [18/Sep/2024 23:22:39] "[33mGET /log HTTP/1.1[0m" 404 -
[2024-09-18 23:22:44,446]^;INFO^;181^;app.py^;render_log_dir()^;req_path:
[2024-09-18 23:22:44,447]^;INFO^;183^;app.py^;render_log_dir()^;Requested path: 
[2024-09-18 23:22:44,458]^;INFO^;224^;_internal.py^;_log()^;127.0.0.1 - - [18/Sep/2024 23:22:44] "GET /housing_logs HTTP/1.1" 200 -
[2024-09-18 23:22:44,561]^;INFO^;224^;_internal.py^;_log()^;127.0.0.1 - - [18/Sep/2024 23:22:44] "[36mGET /static/style.css HTTP/1.1[0m" 304 -
[2024-09-18 23:22:50,644]^;INFO^;181^;app.py^;render_log_dir()^;req_path:log_2024-09-18_23-02-28.log
[2024-09-18 23:22:50,645]^;INFO^;183^;app.py^;render_log_dir()^;Requested path: log_2024-09-18_23-02-28.log
[2024-09-18 23:22:50,656]^;ERROR^;1745^;app.py^;log_exception()^;Exception on /housing_logs/log_2024-09-18_23-02-28.log [GET]
Traceback (most recent call last):
  File "c:\Users\prash\Downloads\Housing_mlops\venv\lib\site-packages\flask\app.py", line 2529, in wsgi_app
    response = self.full_dispatch_request()
  File "c:\Users\prash\Downloads\Housing_mlops\venv\lib\site-packages\flask\app.py", line 1825, in full_dispatch_request
    rv = self.handle_user_exception(e)
  File "c:\Users\prash\Downloads\Housing_mlops\venv\lib\site-packages\flask\app.py", line 1823, in full_dispatch_request
    rv = self.dispatch_request()
  File "c:\Users\prash\Downloads\Housing_mlops\venv\lib\site-packages\flask\app.py", line 1799, in dispatch_request
    return self.ensure_sync(self.view_functions[rule.endpoint])(**view_args)
  File "app.py", line 192, in render_log_dir
    log_df=get_log_data_frame(abs_path)
  File "C:\Users\prash\Downloads\Housing_mlops\house\logger\__init__.py", line 37, in get_log_dataframe
    return log_df[["_log_message"]]
  File "c:\Users\prash\Downloads\Housing_mlops\venv\lib\site-packages\pandas\core\frame.py", line 2912, in __getitem__
    indexer = self.loc._get_listlike_indexer(key, axis=1, raise_missing=True)[1]
  File "c:\Users\prash\Downloads\Housing_mlops\venv\lib\site-packages\pandas\core\indexing.py", line 1254, in _get_listlike_indexer
    self._validate_read_indexer(keyarr, indexer, axis, raise_missing=raise_missing)
  File "c:\Users\prash\Downloads\Housing_mlops\venv\lib\site-packages\pandas\core\indexing.py", line 1298, in _validate_read_indexer
    raise KeyError(f"None of [{key}] are in the [{axis_name}]")
KeyError: "None of [Index(['_log_message'], dtype='object')] are in the [columns]"
[2024-09-18 23:22:50,663]^;INFO^;224^;_internal.py^;_log()^;127.0.0.1 - - [18/Sep/2024 23:22:50] "[35m[1mGET /housing_logs/log_2024-09-18_23-02-28.log HTTP/1.1[0m" 500 -
[2024-09-18 23:25:13,313]^;INFO^;181^;app.py^;render_log_dir()^;req_path:
[2024-09-18 23:25:13,314]^;INFO^;183^;app.py^;render_log_dir()^;Requested path: 
[2024-09-18 23:25:13,325]^;INFO^;224^;_internal.py^;_log()^;127.0.0.1 - - [18/Sep/2024 23:25:13] "GET /housing_logs HTTP/1.1" 200 -
[2024-09-18 23:25:13,394]^;INFO^;224^;_internal.py^;_log()^;127.0.0.1 - - [18/Sep/2024 23:25:13] "[36mGET /static/style.css HTTP/1.1[0m" 304 -
[2024-09-18 23:25:15,291]^;INFO^;181^;app.py^;render_log_dir()^;req_path:log_2024-09-12_23-44-42.log
[2024-09-18 23:25:15,291]^;INFO^;183^;app.py^;render_log_dir()^;Requested path: log_2024-09-12_23-44-42.log
[2024-09-18 23:25:15,361]^;ERROR^;1745^;app.py^;log_exception()^;Exception on /housing_logs/log_2024-09-12_23-44-42.log [GET]
Traceback (most recent call last):
  File "c:\Users\prash\Downloads\Housing_mlops\venv\lib\site-packages\flask\app.py", line 2529, in wsgi_app
    response = self.full_dispatch_request()
  File "c:\Users\prash\Downloads\Housing_mlops\venv\lib\site-packages\flask\app.py", line 1825, in full_dispatch_request
    rv = self.handle_user_exception(e)
  File "c:\Users\prash\Downloads\Housing_mlops\venv\lib\site-packages\flask\app.py", line 1823, in full_dispatch_request
    rv = self.dispatch_request()
  File "c:\Users\prash\Downloads\Housing_mlops\venv\lib\site-packages\flask\app.py", line 1799, in dispatch_request
    return self.ensure_sync(self.view_functions[rule.endpoint])(**view_args)
  File "app.py", line 192, in render_log_dir
    log_df=get_log_data_frame(abs_path)
  File "C:\Users\prash\Downloads\Housing_mlops\house\logger\__init__.py", line 37, in get_log_dataframe
    return log_df[["log_message"]]
  File "c:\Users\prash\Downloads\Housing_mlops\venv\lib\site-packages\pandas\core\frame.py", line 2912, in __getitem__
    indexer = self.loc._get_listlike_indexer(key, axis=1, raise_missing=True)[1]
  File "c:\Users\prash\Downloads\Housing_mlops\venv\lib\site-packages\pandas\core\indexing.py", line 1254, in _get_listlike_indexer
    self._validate_read_indexer(keyarr, indexer, axis, raise_missing=raise_missing)
  File "c:\Users\prash\Downloads\Housing_mlops\venv\lib\site-packages\pandas\core\indexing.py", line 1298, in _validate_read_indexer
    raise KeyError(f"None of [{key}] are in the [{axis_name}]")
KeyError: "None of [Index(['_log_message'], dtype='object')] are in the [columns]"
[2024-09-18 23:25:15,382]^;INFO^;224^;_internal.py^;_log()^;127.0.0.1 - - [18/Sep/2024 23:25:15] "[35m[1mGET /housing_logs/log_2024-09-12_23-44-42.log HTTP/1.1[0m" 500 -
